<?xml version="1.0"?>
<robot xmlns:xacro="http://www.ros.org/wiki/xacro">

    <material name="white"> <color rgba="1 1 1 1" /> </material>
    <material name="blue"> <color rgba="0.2 0.2 1 1" /> </material>
    <material name="black"> <color rgba="0 0 0 1" /> </material>

    <xacro:macro name="inertial_box" params="mass x y z *origin">
        <inertial>
            <xacro:insert_block name="origin"/>
            <mass value="${mass}" />
            <inertia ixx="${(1/12) * mass * (y*y + z*z)}" ixy="0.0" ixz="0.0"
                     iyy="${(1/12) * mass * (x*x + z*z)}" iyz="0.0"
                     izz="${(1/12) * mass * (x*x + y*y)}" />
        </inertial>
    </xacro:macro>

    <xacro:macro name="inertial_cylinder" params="mass length radius *origin">
        <inertial>
            <xacro:insert_block name="origin"/>
            <mass value="${mass}" />
            <inertia ixx="${(1/12) * mass * (3*radius*radius + length*length)}" ixy="0.0" ixz="0.0"
                     iyy="${(1/12) * mass * (3*radius*radius + length*length)}" iyz="0.0"
                     izz="${(1/2) * mass * (radius*radius)}" />
        </inertial>
    </xacro:macro>

    <link name="base_link"></link>

    <joint name="chassis_joint" type="fixed">
        <parent link="base_link"/>
        <child link="chassis"/>
        <origin xyz="0 0 0"/>
    </joint>

    <link name="chassis">
        <visual>
            <origin xyz="0 0 0.075"/>
            <geometry> <box size="0.40 0.28 0.15"/> </geometry>
            <material name="white"/>
        </visual>
        <collision>
            <origin xyz="0 0 0.075"/>
            <geometry> <box size="0.40 0.28 0.15"/> </geometry>
        </collision>
        <xacro:inertial_box mass="0.5" x="0.40" y="0.28" z="0.15">
            <origin xyz="0 0 0.075" rpy="0 0 0"/>
        </xacro:inertial_box>
    </link>

    <xacro:macro name="wheel" params="prefix x_reflect y_reflect">
        <joint name="${prefix}_wheel_joint" type="continuous">
            <parent link="base_link"/>
            <child link="${prefix}_wheel"/>
            <origin xyz="${x_reflect*0.115} ${y_reflect*0.19} 0" rpy="${pi/2} 0 0"/>
            <axis xyz="0 0 -1"/>
        </joint>

        <link name="${prefix}_wheel">
            <visual>
                <geometry> <cylinder radius="0.05" length="0.04"/> </geometry>
                <material name="black"/>
            </visual>
            <collision>
                <geometry> <cylinder radius="0.05" length="0.04"/> </geometry>
            </collision>
            <xacro:inertial_cylinder mass="0.1" length="0.04" radius="0.05">
                <origin xyz="0 0 0" rpy="0 0 0"/>
            </xacro:inertial_cylinder>
        </link>
    </xacro:macro>

    <xacro:wheel prefix="front_left" x_reflect="1" y_reflect="1" />
    <xacro:wheel prefix="front_right" x_reflect="1" y_reflect="-1" />
    <xacro:wheel prefix="back_left" x_reflect="-1" y_reflect="1" />
    <xacro:wheel prefix="back_right" x_reflect="-1" y_reflect="-1" />

</robot>